[2025-06-05 03:21:29,303] INFO django.utils.autoreload Watching for file changes with StatReloader
[2025-06-05 03:21:37,158] INFO django.server "GET / HTTP/1.1" 200 10664
[2025-06-06 02:16:29,021] WARNING django.request Not Found: /api/agent/respond/
[2025-06-06 02:16:29,083] WARNING django.request Not Found: /api/agent/respond/
[2025-06-06 02:19:20,459] ERROR django.request Internal Server Error: /api/agent/respond/
Traceback (most recent call last):
  File "/Users/kiarash/Desktop/project/git/ai-platform/venv/lib/python3.13/site-packages/django/core/handlers/exception.py", line 55, in inner
    response = get_response(request)
  File "/Users/kiarash/Desktop/project/git/ai-platform/venv/lib/python3.13/site-packages/django/core/handlers/base.py", line 192, in _get_response
    wrapped_callback = self.make_view_atomic(callback)
  File "/Users/kiarash/Desktop/project/git/ai-platform/venv/lib/python3.13/site-packages/django/core/handlers/base.py", line 348, in make_view_atomic
    if settings_dict["ATOMIC_REQUESTS"] and alias not in non_atomic_requests:
       ~~~~~~~~~~~~~^^^^^^^^^^^^^^^^^^^
KeyError: 'ATOMIC_REQUESTS'
[2025-06-06 02:19:20,518] ERROR django.request Internal Server Error: /api/agent/respond/
Traceback (most recent call last):
  File "/Users/kiarash/Desktop/project/git/ai-platform/venv/lib/python3.13/site-packages/django/core/handlers/exception.py", line 55, in inner
    response = get_response(request)
  File "/Users/kiarash/Desktop/project/git/ai-platform/venv/lib/python3.13/site-packages/django/core/handlers/base.py", line 192, in _get_response
    wrapped_callback = self.make_view_atomic(callback)
  File "/Users/kiarash/Desktop/project/git/ai-platform/venv/lib/python3.13/site-packages/django/core/handlers/base.py", line 348, in make_view_atomic
    if settings_dict["ATOMIC_REQUESTS"] and alias not in non_atomic_requests:
       ~~~~~~~~~~~~~^^^^^^^^^^^^^^^^^^^
KeyError: 'ATOMIC_REQUESTS'
[2025-06-06 02:20:21,871] ERROR django.request Internal Server Error: /api/agent/respond/
Traceback (most recent call last):
  File "/Users/kiarash/Desktop/project/git/ai-platform/venv/lib/python3.13/site-packages/django/core/handlers/exception.py", line 55, in inner
    response = get_response(request)
  File "/Users/kiarash/Desktop/project/git/ai-platform/venv/lib/python3.13/site-packages/django/core/handlers/base.py", line 192, in _get_response
    wrapped_callback = self.make_view_atomic(callback)
  File "/Users/kiarash/Desktop/project/git/ai-platform/venv/lib/python3.13/site-packages/django/core/handlers/base.py", line 348, in make_view_atomic
    if settings_dict["ATOMIC_REQUESTS"] and alias not in non_atomic_requests:
       ~~~~~~~~~~~~~^^^^^^^^^^^^^^^^^^^
KeyError: 'ATOMIC_REQUESTS'
[2025-06-06 02:20:21,928] ERROR django.request Internal Server Error: /api/agent/respond/
Traceback (most recent call last):
  File "/Users/kiarash/Desktop/project/git/ai-platform/venv/lib/python3.13/site-packages/django/core/handlers/exception.py", line 55, in inner
    response = get_response(request)
  File "/Users/kiarash/Desktop/project/git/ai-platform/venv/lib/python3.13/site-packages/django/core/handlers/base.py", line 192, in _get_response
    wrapped_callback = self.make_view_atomic(callback)
  File "/Users/kiarash/Desktop/project/git/ai-platform/venv/lib/python3.13/site-packages/django/core/handlers/base.py", line 348, in make_view_atomic
    if settings_dict["ATOMIC_REQUESTS"] and alias not in non_atomic_requests:
       ~~~~~~~~~~~~~^^^^^^^^^^^^^^^^^^^
KeyError: 'ATOMIC_REQUESTS'
[2025-06-06 02:21:06,310] ERROR django.request Internal Server Error: /api/agent/respond/
Traceback (most recent call last):
  File "/Users/kiarash/Desktop/project/git/ai-platform/venv/lib/python3.13/site-packages/django/core/handlers/exception.py", line 55, in inner
    response = get_response(request)
  File "/Users/kiarash/Desktop/project/git/ai-platform/venv/lib/python3.13/site-packages/django/core/handlers/base.py", line 192, in _get_response
    wrapped_callback = self.make_view_atomic(callback)
  File "/Users/kiarash/Desktop/project/git/ai-platform/venv/lib/python3.13/site-packages/django/core/handlers/base.py", line 348, in make_view_atomic
    if settings_dict["ATOMIC_REQUESTS"] and alias not in non_atomic_requests:
       ~~~~~~~~~~~~~^^^^^^^^^^^^^^^^^^^
KeyError: 'ATOMIC_REQUESTS'
[2025-06-06 02:21:06,368] ERROR django.request Internal Server Error: /api/agent/respond/
Traceback (most recent call last):
  File "/Users/kiarash/Desktop/project/git/ai-platform/venv/lib/python3.13/site-packages/django/core/handlers/exception.py", line 55, in inner
    response = get_response(request)
  File "/Users/kiarash/Desktop/project/git/ai-platform/venv/lib/python3.13/site-packages/django/core/handlers/base.py", line 192, in _get_response
    wrapped_callback = self.make_view_atomic(callback)
  File "/Users/kiarash/Desktop/project/git/ai-platform/venv/lib/python3.13/site-packages/django/core/handlers/base.py", line 348, in make_view_atomic
    if settings_dict["ATOMIC_REQUESTS"] and alias not in non_atomic_requests:
       ~~~~~~~~~~~~~^^^^^^^^^^^^^^^^^^^
KeyError: 'ATOMIC_REQUESTS'
[2025-06-06 02:23:44,909] ERROR django.request Internal Server Error: /api/agent/respond/
Traceback (most recent call last):
  File "/Users/kiarash/Desktop/project/git/ai-platform/venv/lib/python3.13/site-packages/django/core/handlers/exception.py", line 55, in inner
    response = get_response(request)
  File "/Users/kiarash/Desktop/project/git/ai-platform/venv/lib/python3.13/site-packages/django/core/handlers/base.py", line 192, in _get_response
    wrapped_callback = self.make_view_atomic(callback)
  File "/Users/kiarash/Desktop/project/git/ai-platform/venv/lib/python3.13/site-packages/django/core/handlers/base.py", line 348, in make_view_atomic
    if settings_dict["ATOMIC_REQUESTS"] and alias not in non_atomic_requests:
       ~~~~~~~~~~~~~^^^^^^^^^^^^^^^^^^^
KeyError: 'ATOMIC_REQUESTS'
[2025-06-06 02:23:44,966] ERROR django.request Internal Server Error: /api/agent/respond/
Traceback (most recent call last):
  File "/Users/kiarash/Desktop/project/git/ai-platform/venv/lib/python3.13/site-packages/django/core/handlers/exception.py", line 55, in inner
    response = get_response(request)
  File "/Users/kiarash/Desktop/project/git/ai-platform/venv/lib/python3.13/site-packages/django/core/handlers/base.py", line 192, in _get_response
    wrapped_callback = self.make_view_atomic(callback)
  File "/Users/kiarash/Desktop/project/git/ai-platform/venv/lib/python3.13/site-packages/django/core/handlers/base.py", line 348, in make_view_atomic
    if settings_dict["ATOMIC_REQUESTS"] and alias not in non_atomic_requests:
       ~~~~~~~~~~~~~^^^^^^^^^^^^^^^^^^^
KeyError: 'ATOMIC_REQUESTS'
[2025-06-06 02:24:54,041] ERROR django.request Internal Server Error: /api/agent/respond/
Traceback (most recent call last):
  File "/Users/kiarash/Desktop/project/git/ai-platform/venv/lib/python3.13/site-packages/django/core/handlers/exception.py", line 55, in inner
    response = get_response(request)
  File "/Users/kiarash/Desktop/project/git/ai-platform/venv/lib/python3.13/site-packages/django/core/handlers/base.py", line 192, in _get_response
    wrapped_callback = self.make_view_atomic(callback)
  File "/Users/kiarash/Desktop/project/git/ai-platform/venv/lib/python3.13/site-packages/django/core/handlers/base.py", line 348, in make_view_atomic
    if settings_dict["ATOMIC_REQUESTS"] and alias not in non_atomic_requests:
       ~~~~~~~~~~~~~^^^^^^^^^^^^^^^^^^^
KeyError: 'ATOMIC_REQUESTS'
[2025-06-06 02:24:54,099] ERROR django.request Internal Server Error: /api/agent/respond/
Traceback (most recent call last):
  File "/Users/kiarash/Desktop/project/git/ai-platform/venv/lib/python3.13/site-packages/django/core/handlers/exception.py", line 55, in inner
    response = get_response(request)
  File "/Users/kiarash/Desktop/project/git/ai-platform/venv/lib/python3.13/site-packages/django/core/handlers/base.py", line 192, in _get_response
    wrapped_callback = self.make_view_atomic(callback)
  File "/Users/kiarash/Desktop/project/git/ai-platform/venv/lib/python3.13/site-packages/django/core/handlers/base.py", line 348, in make_view_atomic
    if settings_dict["ATOMIC_REQUESTS"] and alias not in non_atomic_requests:
       ~~~~~~~~~~~~~^^^^^^^^^^^^^^^^^^^
KeyError: 'ATOMIC_REQUESTS'
[2025-06-06 02:25:14,247] ERROR django.request Internal Server Error: /api/agent/respond/
Traceback (most recent call last):
  File "/Users/kiarash/Desktop/project/git/ai-platform/venv/lib/python3.13/site-packages/django/core/handlers/exception.py", line 55, in inner
    response = get_response(request)
  File "/Users/kiarash/Desktop/project/git/ai-platform/venv/lib/python3.13/site-packages/django/core/handlers/base.py", line 192, in _get_response
    wrapped_callback = self.make_view_atomic(callback)
  File "/Users/kiarash/Desktop/project/git/ai-platform/venv/lib/python3.13/site-packages/django/core/handlers/base.py", line 348, in make_view_atomic
    if settings_dict["ATOMIC_REQUESTS"] and alias not in non_atomic_requests:
       ~~~~~~~~~~~~~^^^^^^^^^^^^^^^^^^^
KeyError: 'ATOMIC_REQUESTS'
[2025-06-06 02:25:14,304] ERROR django.request Internal Server Error: /api/agent/respond/
Traceback (most recent call last):
  File "/Users/kiarash/Desktop/project/git/ai-platform/venv/lib/python3.13/site-packages/django/core/handlers/exception.py", line 55, in inner
    response = get_response(request)
  File "/Users/kiarash/Desktop/project/git/ai-platform/venv/lib/python3.13/site-packages/django/core/handlers/base.py", line 192, in _get_response
    wrapped_callback = self.make_view_atomic(callback)
  File "/Users/kiarash/Desktop/project/git/ai-platform/venv/lib/python3.13/site-packages/django/core/handlers/base.py", line 348, in make_view_atomic
    if settings_dict["ATOMIC_REQUESTS"] and alias not in non_atomic_requests:
       ~~~~~~~~~~~~~^^^^^^^^^^^^^^^^^^^
KeyError: 'ATOMIC_REQUESTS'
[2025-06-06 02:38:20,193] ERROR django.request Internal Server Error: /api/agent/respond/
[2025-06-06 02:46:46,278] INFO django.utils.autoreload Watching for file changes with StatReloader
[2025-06-06 02:47:06,527] ERROR django.request Internal Server Error: /api/agent/respond/
[2025-06-06 02:47:06,527] ERROR django.server "POST /api/agent/respond/ HTTP/1.1" 500 488
[2025-06-06 02:47:20,713] INFO django.server "POST /api/agent/respond/ HTTP/1.1" 200 27
[2025-06-06 03:03:49,409] ERROR django.request Internal Server Error: /api/agent/respond/
[2025-06-06 03:03:49,424] ERROR django.request Internal Server Error: /api/agent/respond/
[2025-06-06 03:03:49,439] ERROR django.request Internal Server Error: /api/agent/respond/
